2021-03-01 17:10:42,441 | INFO  | main | com.zy.game.ZyServer | netty server loading success
2021-03-01 17:23:52,589 | WARN  | nioEventLoopGroup-3-3 | io.netty.channel.DefaultChannelPipeline | An exceptionCaught() event was fired, and it reached at the tail of the pipeline. It usually means the last handler in the pipeline did not handle the exception.
java.io.IOException: 远程主机强迫关闭了一个现有的连接。
	at sun.nio.ch.SocketDispatcher.read0(Native Method)
	at sun.nio.ch.SocketDispatcher.read(Unknown Source)
	at sun.nio.ch.IOUtil.readIntoNativeBuffer(Unknown Source)
	at sun.nio.ch.IOUtil.read(Unknown Source)
	at sun.nio.ch.SocketChannelImpl.read(Unknown Source)
	at io.netty.buffer.PooledByteBuf.setBytes(PooledByteBuf.java:253)
	at io.netty.buffer.AbstractByteBuf.writeBytes(AbstractByteBuf.java:1134)
	at io.netty.channel.socket.nio.NioSocketChannel.doReadBytes(NioSocketChannel.java:350)
	at io.netty.channel.nio.AbstractNioByteChannel$NioByteUnsafe.read(AbstractNioByteChannel.java:151)
	at io.netty.channel.nio.NioEventLoop.processSelectedKey(NioEventLoop.java:714)
	at io.netty.channel.nio.NioEventLoop.processSelectedKeysOptimized(NioEventLoop.java:650)
	at io.netty.channel.nio.NioEventLoop.processSelectedKeys(NioEventLoop.java:576)
	at io.netty.channel.nio.NioEventLoop.run(NioEventLoop.java:493)
	at io.netty.util.concurrent.SingleThreadEventExecutor$4.run(SingleThreadEventExecutor.java:989)
	at io.netty.util.internal.ThreadExecutorMap$2.run(ThreadExecutorMap.java:74)
	at io.netty.util.concurrent.FastThreadLocalRunnable.run(FastThreadLocalRunnable.java:30)
	at java.lang.Thread.run(Unknown Source)
2021-03-01 17:24:04,294 | INFO  | main | com.zy.game.ZyServer | netty server loading success
2021-03-01 17:27:57,176 | INFO  | main | com.zy.game.ZyServer | netty server loading success
2021-03-01 17:32:11,747 | INFO  | main | com.zy.game.ZyServer | netty server loading success
2021-03-01 17:34:33,728 | INFO  | main | com.zy.game.ZyServer | netty server loading success
